Workbook
Name __aan1: #REF!
Name __aca1: 0
Name __acb1: SUMIF(__Cum31,206,__sfd1)
Name __acb1: SUMIF(__Cum31,206,__sfd1)
Name __acb1: SUMIF(__Cum31,206,__sfd1)
Name __adn1: #REF!
Name __aea1: SUMIF(__cum41,2811,__sfc1)+SUMIF(__cum51,29191,__sfc1)
Name __aea1: SUMIF(__cum41,2811,__sfc1)+SUMIF(__cum51,29191,__sfc1)
Name __aea1: SUMIF(__cum41,2811,__sfc1)+SUMIF(__cum51,29191,__sfc1)
Name __aeb1: SUMIF(__Cum31,211,__sfd1)+SUMIF(__cum41,2191,__sfd1)
Name __aeb1: SUMIF(__Cum31,211,__sfd1)+SUMIF(__cum41,2191,__sfd1)
Name __aeb1: SUMIF(__Cum31,211,__sfd1)+SUMIF(__cum41,2191,__sfd1)
Name __afa1: SUMIF(__cum41,2812,__sfc1)+SUMIF(__cum41,2913,__sfc1)+SUMIF(__cum41,2814,__sfc1)+SUMIF(__cum41,2912,__sfc1)+SUMIF(__cum41,2813,__sfc1)+SUMIF(__cum41,2914,__sfc1)+SUMIF(__cum51,29192,__sfc1)
Name __afa1: SUMIF(__cum41,2812,__sfc1)+SUMIF(__cum41,2913,__sfc1)+SUMIF(__cum41,2814,__sfc1)+SUMIF(__cum41,2912,__sfc1)+SUMIF(__cum41,2813,__sfc1)+SUMIF(__cum41,2914,__sfc1)+SUMIF(__cum51,29192,__sfc1)
Name __afa1: SUMIF(__cum41,2812,__sfc1)+SUMIF(__cum41,2913,__sfc1)+SUMIF(__cum41,2814,__sfc1)+SUMIF(__cum41,2912,__sfc1)+SUMIF(__cum41,2813,__sfc1)+SUMIF(__cum41,2914,__sfc1)+SUMIF(__cum51,29192,__sfc1)
Name __afb1: SUMIF(__Cum31,212,__sfd1)+SUMIF(__Cum31,213,__sfd1)+SUMIF(__Cum31,214,__sfd1)+SUMIF(__cum41,2193,__sfd1)
Name __afb1: SUMIF(__Cum31,212,__sfd1)+SUMIF(__Cum31,213,__sfd1)+SUMIF(__Cum31,214,__sfd1)+SUMIF(__cum41,2193,__sfd1)
Name __afb1: SUMIF(__Cum31,212,__sfd1)+SUMIF(__Cum31,213,__sfd1)+SUMIF(__Cum31,214,__sfd1)+SUMIF(__cum41,2193,__sfd1)
Name __aga1: SUMIF(__cum41,2815,__sfc1)+SUMIF(__cum41,2816,__sfc1)+SUMIF(__cum41,2915,__sfc1)+SUMIF(__cum41,2916,__sfc1)
Name __aga1: SUMIF(__cum41,2815,__sfc1)+SUMIF(__cum41,2816,__sfc1)+SUMIF(__cum41,2915,__sfc1)+SUMIF(__cum41,2916,__sfc1)
Name __aga1: SUMIF(__cum41,2815,__sfc1)+SUMIF(__cum41,2816,__sfc1)+SUMIF(__cum41,2915,__sfc1)+SUMIF(__cum41,2916,__sfc1)
Name __agb1: SUMIF(__Cum31,215,__sfd1)+SUMIF(__Cum31,216,__sfd1)
Name __agb1: SUMIF(__Cum31,215,__sfd1)+SUMIF(__Cum31,216,__sfd1)
Name __agb1: SUMIF(__Cum31,215,__sfd1)+SUMIF(__Cum31,216,__sfd1)
Name __aha1: SUMIF(__cum41,2817,__sfc1)+SUMIF(__cum41,2818,__sfc1)+SUMIF(__cum41,2917,__sfc1)+SUMIF(__cum41,2918,__sfc1)+SUMIF(__cum51,29193,__sfc1)
Name __aha1: SUMIF(__cum41,2817,__sfc1)+SUMIF(__cum41,2818,__sfc1)+SUMIF(__cum41,2917,__sfc1)+SUMIF(__cum41,2918,__sfc1)+SUMIF(__cum51,29193,__sfc1)
Name __aha1: SUMIF(__cum41,2817,__sfc1)+SUMIF(__cum41,2818,__sfc1)+SUMIF(__cum41,2917,__sfc1)+SUMIF(__cum41,2918,__sfc1)+SUMIF(__cum51,29193,__sfc1)
Name __ahb1: SUMIF(__Cum31,217,__sfd1)+SUMIF(__Cum31,218,__sfd1)+SUMIF(__cum41,2198,__sfd1)
Name __ahb1: SUMIF(__Cum31,217,__sfd1)+SUMIF(__Cum31,218,__sfd1)+SUMIF(__cum41,2198,__sfd1)
Name __ahb1: SUMIF(__Cum31,217,__sfd1)+SUMIF(__Cum31,218,__sfd1)+SUMIF(__cum41,2198,__sfd1)
Name __ain1: #REF!
Name __aja1: SUMIF(__Cum31,282,__sfc1)+SUMIF(__Cum31,292,__sfc1)
Name __aja1: SUMIF(__Cum31,282,__sfc1)+SUMIF(__Cum31,292,__sfc1)
Name __aja1: SUMIF(__Cum31,282,__sfc1)+SUMIF(__Cum31,292,__sfc1)
Name __ajb1: SUMIF(__cum21,22,__sfd1)
Name __ajb1: SUMIF(__cum21,22,__sfd1)
Name __ajb1: SUMIF(__cum21,22,__sfd1)
Name __akb1: SUMIF(__Cum31,231,__sfd1)+SUMIF(__Cum31,232,__sfd1)+SUMIF(__Cum31,233,__sfd1)+SUMIF(__Cum31,237,__sfd1)+SUMIF(__cum41,2391,__sfd1)
Name __akb1: SUMIF(__Cum31,231,__sfd1)+SUMIF(__Cum31,232,__sfd1)+SUMIF(__Cum31,233,__sfd1)+SUMIF(__Cum31,237,__sfd1)+SUMIF(__cum41,2391,__sfd1)
Name __akb1: SUMIF(__Cum31,231,__sfd1)+SUMIF(__Cum31,232,__sfd1)+SUMIF(__Cum31,233,__sfd1)+SUMIF(__Cum31,237,__sfd1)+SUMIF(__cum41,2391,__sfd1)
Name __aqn1: #REF!
Name __axa1: 0
Name __axb1: SUMIF(__Cum31,202,__sfd1)
Name __axb1: SUMIF(__Cum31,202,__sfd1)
Name __axb1: SUMIF(__Cum31,202,__sfd1)
Name __AYA1: 0
Name __AYB1: SUMIF(__Cum31,202,__sfd1)
Name __AYB1: SUMIF(__Cum31,202,__sfd1)
Name __AYB1: SUMIF(__Cum31,202,__sfd1)
Name __azn1: #REF!
Name __bcn1: #REF!
Name __bdn1: #REF!
Name __ben1: #REF!
Name __bfe1: #REF!
Name __bfe2: #REF!
Name __bfn1: #REF!
Name __bhn1: #REF!
Name __bin1: #REF!
Name __bjn1: #REF!
Name __bkn1: #REF!

Sheet README
C6: BUDGET NOTES FOR ACTWATCH LITE STUDY
B7: ACTwatch LITE Sampling Tool
B8: This workbook provides step-by-step guidance to help users calculate and select an outlet sample for an ACTwatch Lite survey using probability proportional to size (PPS) sampling.
B10: OVERVIEW | C10: This tool uses a standard sample size formula for estimating precision, and a probability proportional to size (PPS) approach to support users in determining the required sample size and selecting study areas/clusters to be censused. The PPS method helps ensure that the likelihood of inclusion of a geographic area in the study is relative to the size of its population. It has been designed for use in ACTwatch Lite studies, where sampling must account for varying cluster sizes and outlet distributions. The main sampling approach adopted for ACTwatch Lite surveys is to sample a set of administrative units (geographical clusters) with a corresponding population of around 10,000 to 15,000 inhabitants. Sampling units may be administrative (the name varies by context, but might be called "wards", "arrondissements", "LGAs", etc. ) or custom-defined zones used in the field. Before using the tool, make sure that your team has established their desired levels of geographic coverage and study representativeness (i.e. nationally, subnationally, or other level); possesses a complete list of geographic clusters and populations within study boundaries; determined if, and by which variable(s), the sample will be stratified; and possesses data or estimates on the number of key private sector outlets in each geographic cluster, for each stratum. Note that this tool is designed for the primary (retail outlet) sample. The sampling for wholesalers is based on data collected from the retail outlet sample, and so is not considered in this tool.
B12: TOOL STRUCTURE | C12: This tool will prompt you through a series of inputs and calculations to identify the minimum sample size requirements for retail outlets needed to estimate key study indicators at your desired level of precision:
C13: TAB NAME | D13: Description
C14: 1 INPUTS | D14: Input survey assumptions, target indicators, and known population parameters.
C15: 2 CALC | D15: Auto-calculates required sample size and number of clusters based on inputs.
C16: 3 PPS | D16: Generates a probability-based sample using uploaded sampling frame data.
B19: EXPECTED OUTPUTS | C19: - Minimum sample size required - Number of clusters needed - Selected PPS sample list (copy-paste ready for fieldwork tools)
B21: INSTRUCTIONS FOR USE | C21: Prepare your sampling frame: Collect a list of administrative units (e.g., wards or aire de sante) and associated population data. This should be saved as a separate Excel or CSV file and relevant columns copied here for use in the PPS selection step.
C22: Go to Tab 1 – INPUTS: - Use the checklist to ensure you have access to all relevant information (or are able to make sensible estimates) for key inputs in this tab. - Enter the country and study details: input key data to calibrate the tool with the information necessary to calculate your sample. You will first be prompted to enter the name of the administrative unit containing a population of 10-15k people, stratum you wish the sample should include, and key outlet types that the sample should be based upon. - The tool will then automatically generate a table, which must be filled out with the number of each outlet type in each stratum. - Input assumptions and statistical variables such as desired confidence level, margin of error, population proportion, population size, design effect, and non-response/ refusal rate. If you do not know one or more of these variables, you may maintain the default values (Default calculations assume a 95% confidence level, 5% margin of error, 50% population proportion, a design effect of 2 and non-response rate of 5%. However, please adjust as required according to the specific requirements of your study)
C23: Check Tab 2 – CALC: - The tool will automatically calculate the required sample size, number of clusters, and outlets per cluster based on calculations made in the previous tab. - The estimated number of each outlet type required to achieve your desired precision will appear in cell D6. - If your study includes strata, a table will be automatically generated to display the minimum number of primary sampling units required to achieve the required sample size in each stratum beginning in row 10. - Review and adjust assumptions if needed.
C24: Use Tab 3 – PPS: The PPS tab is a template generating a PPS sample for *one strata at a time (i.e. if study is not national)* - Start by pasting your cleaned sampling frame (primary sampling unit names along with their corresponding population size) in Columns A-C of the main table (Beginning in cell A21). - In cell E15, type the random number you see in cell E14 that will be used for the sampling (otherwise the number will keep changing each time you open or edit the workbook). - In the table beginning in I12, manually create a numerical list with the number of clusters corresponding to the value automatically generated in cell E12 (in the provided example, the value is 7, so we manually typed the numbers 1-7 descending from cell I14 to I21). - Doing so will prompt the main table (Beginning in cell A21) to select the final list of clusters for your PPS sample. Selected clusters are indicated as those in the rows with green "Yes" values in column E. - Copy+Paste your final sampling results for the given Stratum (table 5.2) as plain text in to a new tab and label with the stratum name (we have provided a reference 'example Urban North' tab in this tool) Repeat Tab 3 steps for each Strata
B26: ASSUMPTIONS | C26: - The tool assumes that all eligible outlets in selected clusters will be visited. - This tool does not account for longitudinal data collection, or for more complex multistage cluster samples which may be more suitable for some study designs. Consult a statistician for these alternative approaches. - This approach assumes that population and outlet count within a given area are positively correlated - This tool should act as a guide, but will require adaptation to the specific study design you are implementing. LIST ADDITIONAL ASUMPTIONS FOR YOUR COUNTRY/ IMPLEMENTATION HERE. CONSIDER: - Simple random sampling of geographic units for the study from higher level clusters - Design effect to account for clustering - Target precision and confidence level should align with your study objectives - Adjustments for non-response are built in (adjust as needed)

Sheet 1. INPUTS
B1: Follow each step presented below. Fill in information in each of the yellow highlighted cells. Example or reference information is in purple.
B2: Fill in information in each of the yellow highlighted cells.
B3: Example or reference information is in purple.
B5: STEP 1: | C5: Before using this tool, you should be able to answer "yes" to the following questions:
E7: Yes?
C8: 1.1 Have you established what level of geographic coverage, and level of representativeness you require for this study? | E8: FALSE
C9: For the purposes of estimating a sample size, ACTwatch Lite's primary sampling unit is a geographic area with 10-15k population. These are typically called "wards", "aires de santé", or "commune".
C10: 1.2 Do you have a complete listing of all administrative units (i.e. clusters) of 10-15k population in size in the study areas/ nationally, including their population sizes? | E10: FALSE
C11: NOTE !!! The PPS method is only as reliable as the accuracy of the population estimates used. Outdated or inaccurate data could bias cluster selection. Validate population data before use to ensure accuracy e.g by cross-checking different sources
C12: 1.3 Have you established whether you need to stratify your sample (e.g. By urbanicity, or some other characteristic)? | E12: FALSE
C13: 1.4 Do you have data, or estimates, of the number of key private sector outlets per 10-15k population administrative unit (cluster)? | E13: FALSE
B15: STEP 2: | C15: Once all questions are checked, please proceed to the next steps below:
E16: Type your answers below:
C17: 2.1 What is the name used for the clusters, or primary sampling unit, that will be used for this study (i.e. administrative or otherwise delininated areas with a population of approximatly 10-15k)? List here: | E17: [cluster name e.g. ward, arrondissement, etc]
C19: 2.2 If this study will be stratified by higher administrative units, list these here (e.g. if the study is conducted in 5 states and not nationally representative -- list 5 states here): | E19: [strata 1 e.g. state 1]
E20: [strata 2 e.g. state 2]
E21: [strata 3 e.g. state 3]
E22: [strata 4 e.g. state 4]
E23: [strata 5 e.g. state 5]
C30: 2.3 Which are the key outlets you would like to base your sample size on? (LIST BELOW) IF THERE ARE MORE THEN 7 OUTLET TYPES, ADD ROWS HERE AND COLUMNS WITH COPIED FORMULA IN THE TABLE BELOW (2.4) | E30: [outlet type 1 e.g. pharmacy]
E31: [outlet type 1 e.g. hospital]
E32: [outlet type 1 e.g. lab]
E33: [outlet type 1 e.g. drug shop]
C38: =_xlfn.CONCAT("2.4 Complete the following table with estimates for the number of each outlet type per ",E17," for each stratum") -> 2.4 Complete the following table with estimates for the number of each outlet type per [cluster name e.g. ward, arrondissement, etc] for each stratum | F38: =IF(ISBLANK(E30),"-",E30) -> [outlet type 1 e.g. pharmacy] | G38: =IF(ISBLANK(E31),"-",E31) -> [outlet type 1 e.g. hospital] | H38: =IF(ISBLANK(E32),"-",E32) -> [outlet type 1 e.g. lab] | I38: =IF(ISBLANK(E33),"-",E33) -> [outlet type 1 e.g. drug shop] | J38: =IF(ISBLANK(E34),"-",E34) -> - | K38: =IF(ISBLANK(E35),"-",E35) -> - | L38: =IF(ISBLANK(E36),"-",E36) -> -
E39: =IF(ISBLANK(E19),"-",E19) -> [strata 1 e.g. state 1] | F39: 29 | G39: 25 | H39: 77 | I39: 34
E40: =IF(ISBLANK(E20),"-",E20) -> [strata 2 e.g. state 2] | F40: 11 | G40: 9 | H40: 43 | I40: 12
E41: =IF(ISBLANK(E21),"-",E21) -> [strata 3 e.g. state 3] | F41: 100 | G41: 5 | H41: 88 | I41: 5
E42: =IF(ISBLANK(E22),"-",E22) -> [strata 4 e.g. state 4] | F42: 20 | G42: 2 | H42: 23 | I42: 83
E43: =IF(ISBLANK(E23),"-",E23) -> [strata 5 e.g. state 5] | F43: 45 | G43: 15 | H43: 34 | I43: 3
E44: =IF(ISBLANK(E24),"-",E24) -> -
E45: =IF(ISBLANK(E25),"-",E25) -> -
E46: =IF(ISBLANK(E26),"-",E26) -> -
E47: =IF(ISBLANK(E27),"-",E27) -> -
E48: =IF(ISBLANK(E28),"-",E28) -> -
B50: STEP 3: | C50: Complete the following information (consult a statistician or use default values if uncertain)
C52: 3.1 Confidence level (95% is default) | E52: 0.95
C53: 3.2 Margin of error (5% is default) | E53: 0.05
C54: 3.3 Population proportion (50% if unsure) | E54: 0.5
C55: 3.4 Population size (leave blank if unsure) | E55: 100
C56: 3.5 Design effect (default=2; increase if you are using a cluster sample) | E56: 2
...

Sheet 2. CALC
B1: Follow each step presented below. Fill in information in each of the yellow highlighted cells. Example or reference information is in purple.
B2: Fill in information in each of the yellow highlighted cells.
B3: Example or reference information is in purple.
B6: STEP 4: | C6: Sample size estimates
C8: =_xlfn.CONCAT("This tab shows the minimum number of primary sampling units (",'1. INPUTS'!E18,"s) to include in your study for each stratum") -> This tab shows the minimum number of primary sampling units (s) to include in your study for each stratum
C10: The estimated number of each outlet type (listed in step 2.3) required to achieve desired sampling precision: | D10: =IF(ISBLANK('1. INPUTS'!E55),('1. INPUTS'!E57+1*('1. INPUTS'!E56*(((_xlfn.NORM.S.INV(1-((1-'1. INPUTS'!E52)/2)))^2*('1. INPUTS'!E54*(1-'1. INPUTS'!E54))/('1. INPUTS'!E53)^2)))),('1. INPUTS'!E57+1*('1. INPUTS'!E56*((((_xlfn.NORM.S.INV(1-((1-'1. INPUTS'!E52)/2)))^2*('1. INPUTS'!E54*(1-'1. INPUTS'!E54))/('1. INPUTS'!E53)^2))/(1+((_xlfn.NORM.S.INV(1-((1-'1. INPUTS'!E52)/2)))^2*('1. INPUTS'!E54*(1-'1. INPUTS'!E54))/(('1. INPUTS'!E53)^2*'1. INPUTS'!E55))))))) -> 158.74014
C12: =_xlfn.CONCAT("This means ",ROUNDUP(D10,0), " or more outlets per stratum are needed to have a confidence level of ",'1. INPUTS'!E52," that the real value is within +/-", '1. INPUTS'!E53," of the measured/surveyed value.") -> This means 159 or more outlets per stratum are needed to have a confidence level of 0.95 that the real value is within +/-0.05 of the measured/surveyed value.
C14: Stratum: | D14: =_xlfn.CONCAT("Minimum number of ",'1. INPUTS'!E17,"s needed to get required sample size in each stratum") -> Minimum number of [cluster name e.g. ward, arrondissement, etc]s needed to get required sample size in each stratum
C15: =IF(ISBLANK('1. INPUTS'!E39),"-",'1. INPUTS'!E39) -> [strata 1 e.g. state 1] | D15: =IF(C15="-","",ROUNDUP($D$10/(MIN('1. INPUTS'!F39:L39)),0)) -> 7
C16: =IF(ISBLANK('1. INPUTS'!E40),"-",'1. INPUTS'!E40) -> [strata 2 e.g. state 2] | D16: =IF(C16="-","",ROUNDUP($D$10/(MIN('1. INPUTS'!F40:L40)),0)) -> 18
C17: =IF(ISBLANK('1. INPUTS'!E41),"-",'1. INPUTS'!E41) -> [strata 3 e.g. state 3] | D17: =IF(C17="-","",ROUNDUP($D$10/(MIN('1. INPUTS'!F41:L41)),0)) -> 32
C18: =IF(ISBLANK('1. INPUTS'!E42),"-",'1. INPUTS'!E42) -> [strata 4 e.g. state 4] | D18: =IF(C18="-","",ROUNDUP($D$10/(MIN('1. INPUTS'!F42:L42)),0)) -> 80
C19: =IF(ISBLANK('1. INPUTS'!E43),"-",'1. INPUTS'!E43) -> [strata 5 e.g. state 5] | D19: =IF(C19="-","",ROUNDUP($D$10/(MIN('1. INPUTS'!F43:L43)),0)) -> 53
C20: =IF(ISBLANK('1. INPUTS'!E44),"-",'1. INPUTS'!E44) -> - | D20: =IF(C20="-","",ROUNDUP($D$10/(MIN('1. INPUTS'!F44:L44)),0))
C21: =IF(ISBLANK('1. INPUTS'!E45),"-",'1. INPUTS'!E45) -> - | D21: =IF(C21="-","",ROUNDUP($D$10/(MIN('1. INPUTS'!F45:L45)),0))
C22: =IF(ISBLANK('1. INPUTS'!E46),"-",'1. INPUTS'!E46) -> - | D22: =IF(C22="-","",ROUNDUP($D$10/(MIN('1. INPUTS'!F46:L46)),0))
C23: =IF(ISBLANK('1. INPUTS'!E47),"-",'1. INPUTS'!E47) -> - | D23: =IF(C23="-","",ROUNDUP($D$10/(MIN('1. INPUTS'!F47:L47)),0))
C24: =IF(ISBLANK('1. INPUTS'!E48),"-",'1. INPUTS'!E48) -> - | D24: =IF(C24="-","",ROUNDUP($D$10/(MIN('1. INPUTS'!F48:L48)),0))
B27: STEP 5: | C27: Go to the next tab (PPS INSTRUCTIONS)
B28: >>>>>>>>>>>>

Sheet 3. PPS
B1: Follow each step presented below. Fill in information in each of the yellow highlighted cells. Example or reference information is in purple.
B2: Fill in information in each of the yellow highlighted cells.
B3: Example or reference information is in purple.
B6: STEP 5: Complete the following steps to use the Probability Proportional to Size (PPS) sample template
B8: The PPS tab is a template for a Probability Proportional to Size (PPS) sample. In order to design a PPS sample, you will need to have population data at relevant administrative units for the study areas (country/ sub-national areas). A complete list of lower level administrative units is also required.
B9: !!! REPEAT STEPS FOR EACH STRATA WHERE APPLICABLE !!!
B11: 5.1 List the primary sampling units along with their population sizes in Columns A-C in the table below (Row 20). Each cluster has a specific population size.
B13: 5.2 The template will calculate cumulative population, SI, and RS to identify which clusters to select; Type the RS in to row 20 to complete other tables.
D15: Strata for PPS: | E15: =A28 -> [strata 1 e.g. state 1] | F15: The stratum name is pulled form A23 below. Update table 5.1 for each strata to get seperate results for each, where applicable | I15: !!! REPEAT STEPS FOR EACH STRATA WHERE APPLICABLE !!!
C16: The cumulative population size will calculate in Column D. The last value in Column D represents the Total Population. | D16: Total population | E16: =MAX(D:D) -> 1759341 | I16: (5.2) Create numerical list up to the value of the number of clusters to select from cell E12
C17: Determine the number of clusters (#) to be sampled. | D17: Number clusters to select | E17: =VLOOKUP(E15, '2. CALC'!C14:D24, 2, FALSE) -> 7 | I17: Selected clusters (#) | J17: random id | K17: corresponding cluster
C18: Calculate the Sampling Interval (SI) by dividing the total population by the number of clusters to be sampled. | D18: Sampling interval | E18: =ROUND(E16/E17,0) -> 251334 | I18: ------ | J18: 0 | K18: ------
C19: Select a Random Start (RS): Choose a random number between 1 and SI. The first cluster to be sampled will be the one whose cumulative population (Column D) contains this number. | D19: Auto-generated random starting number (changes each time you open the workbook) | E19: =RANDBETWEEN(1,E18) -> 189177 | I19: 1 | J19: =IF(I19>0, $E$20+J18, ".") -> 999 | K19: =IF(INDEX(B$28:B$1007, MATCH(J19, D$28:D$1007, 1))=0, ".", INDEX(B$28:B$1007, MATCH(J19, D$28:D$1007, 1))) -> Cluster 1
D20: Type (don’t copy/paste) the random number from cell E14 here that will be used for the sampling: | E20: 999 | I20: 2 | J20: =IF(I20>0, $E$20+J19, ".") -> 1998 | K20: =IF(INDEX(B$28:B$1007, MATCH(J20, D$28:D$1007, 1))=0, ".", INDEX(B$28:B$1007, MATCH(J20, D$28:D$1007, 1))) -> Cluster 1
I21: 3 | J21: =IF(I21>0, $E$20+J20, ".") -> 2997 | K21: =IF(INDEX(B$28:B$1007, MATCH(J21, D$28:D$1007, 1))=0, ".", INDEX(B$28:B$1007, MATCH(J21, D$28:D$1007, 1))) -> Cluster 1
I22: 4 | J22: =IF(I22>0, $E$20+J21, ".") -> 3996 | K22: =IF(INDEX(B$28:B$1007, MATCH(J22, D$28:D$1007, 1))=0, ".", INDEX(B$28:B$1007, MATCH(J22, D$28:D$1007, 1))) -> Cluster 1
B23: 5.3 Selected clusters are identified in column E below | I23: 5 | J23: =IF(I23>0, $E$20+J22, ".") -> 4995 | K23: =IF(INDEX(B$28:B$1007, MATCH(J23, D$28:D$1007, 1))=0, ".", INDEX(B$28:B$1007, MATCH(J23, D$28:D$1007, 1))) -> Cluster 1
I24: 6 | J24: =IF(I24>0, $E$20+J23, ".") -> 5994 | K24: =IF(INDEX(B$28:B$1007, MATCH(J24, D$28:D$1007, 1))=0, ".", INDEX(B$28:B$1007, MATCH(J24, D$28:D$1007, 1))) -> Cluster 1
A25: (5.1) Insert administrative units and population per cluster here: | I25: 7 | J25: =IF(I25>0, $E$20+J24, ".") -> 6993 | K25: =IF(INDEX(B$28:B$1007, MATCH(J25, D$28:D$1007, 1))=0, ".", INDEX(B$28:B$1007, MATCH(J25, D$28:D$1007, 1))) -> Cluster 1
A26: Column A | B26: Column B | C26: Column C | D26: Column D | E26: Column E | J26: =IF(I26>0, $E$20+J25, ".") -> . | K26: =IF(INDEX(B$28:B$1007, MATCH(J26, D$28:D$1007, 1))=0, ".", INDEX(B$28:B$1007, MATCH(J26, D$28:D$1007, 1))) -> .
A27: Stratum | B27: Cluster/ Study area | C27: Population | D27: Cumulative population | E27: Selected for PPS sample? | J27: =IF(I27>0, $E$20+J26, ".") -> . | K27: =IF(INDEX(B$28:B$1007, MATCH(J27, D$28:D$1007, 1))=0, ".", INDEX(B$28:B$1007, MATCH(J27, D$28:D$1007, 1))) -> .
A28: [strata 1 e.g. state 1] | B28: Cluster 1 | C28: 78 | D28: =IF(C28="", "-", C28) -> 78 | E28: =IF(IFERROR(VLOOKUP(B28, K$18:K$1006, 1, FALSE), "no")="no", "no", "yes") -> yes | J28: =IF(I28>0, $E$20+J27, ".") -> . | K28: =IF(INDEX(B$28:B$1007, MATCH(J28, D$28:D$1007, 1))=0, ".", INDEX(B$28:B$1007, MATCH(J28, D$28:D$1007, 1))) -> .
A29: [strata 1 e.g. state 1] | B29: Cluster 2 | C29: 26231 | D29: =IF(C29="","-",D28+C29) -> 26309 | E29: =IF(IFERROR(VLOOKUP(B29, K$18:K$1006, 1, FALSE), "no")="no", "no", "yes") -> no | J29: =IF(I29>0, $E$20+J28, ".") -> . | K29: =IF(INDEX(B$28:B$1007, MATCH(J29, D$28:D$1007, 1))=0, ".", INDEX(B$28:B$1007, MATCH(J29, D$28:D$1007, 1))) -> .
A30: [strata 1 e.g. state 1] | B30: Cluster 3 | C30: 50318 | D30: =IF(C30="","-",D29+C30) -> 76627 | E30: =IF(IFERROR(VLOOKUP(B30, K$18:K$1006, 1, FALSE), "no")="no", "no", "yes") -> no | J30: =IF(I30>0, $E$20+J29, ".") -> . | K30: =IF(INDEX(B$28:B$1007, MATCH(J30, D$28:D$1007, 1))=0, ".", INDEX(B$28:B$1007, MATCH(J30, D$28:D$1007, 1))) -> .
A31: [strata 1 e.g. state 1] | B31: Cluster 4 | C31: 18118 | D31: =IF(C31="","-",D30+C31) -> 94745 | E31: =IF(IFERROR(VLOOKUP(B31, K$18:K$1006, 1, FALSE), "no")="no", "no", "yes") -> no | J31: =IF(I31>0, $E$20+J30, ".") -> . | K31: =IF(INDEX(B$28:B$1007, MATCH(J31, D$28:D$1007, 1))=0, ".", INDEX(B$28:B$1007, MATCH(J31, D$28:D$1007, 1))) -> .
A32: [strata 1 e.g. state 1] | B32: Cluster 5 | C32: 86148 | D32: =IF(C32="","-",D31+C32) -> 180893 | E32: =IF(IFERROR(VLOOKUP(B32, K$18:K$1006, 1, FALSE), "no")="no", "no", "yes") -> no | J32: =IF(I32>0, $E$20+J31, ".") -> . | K32: =IF(INDEX(B$28:B$1007, MATCH(J32, D$28:D$1007, 1))=0, ".", INDEX(B$28:B$1007, MATCH(J32, D$28:D$1007, 1))) -> .
A33: [strata 1 e.g. state 1] | B33: Cluster 6 | C33: 76024 | D33: =IF(C33="","-",D32+C33) -> 256917 | E33: =IF(IFERROR(VLOOKUP(B33, K$18:K$1006, 1, FALSE), "no")="no", "no", "yes") -> no | J33: =IF(I33>0, $E$20+J32, ".") -> . | K33: =IF(INDEX(B$28:B$1007, MATCH(J33, D$28:D$1007, 1))=0, ".", INDEX(B$28:B$1007, MATCH(J33, D$28:D$1007, 1))) -> .
A34: [strata 1 e.g. state 1] | B34: Cluster 7 | C34: 498 | D34: =IF(C34="","-",D33+C34) -> 257415 | E34: =IF(IFERROR(VLOOKUP(B34, K$18:K$1006, 1, FALSE), "no")="no", "no", "yes") -> no | J34: =IF(I34>0, $E$20+J33, ".") -> . | K34: =IF(INDEX(B$28:B$1007, MATCH(J34, D$28:D$1007, 1))=0, ".", INDEX(B$28:B$1007, MATCH(J34, D$28:D$1007, 1))) -> .
A35: [strata 1 e.g. state 1] | B35: Cluster 8 | C35: 19696 | D35: =IF(C35="","-",D34+C35) -> 277111 | E35: =IF(IFERROR(VLOOKUP(B35, K$18:K$1006, 1, FALSE), "no")="no", "no", "yes") -> no | J35: =IF(I35>0, $E$20+J34, ".") -> . | K35: =IF(INDEX(B$28:B$1007, MATCH(J35, D$28:D$1007, 1))=0, ".", INDEX(B$28:B$1007, MATCH(J35, D$28:D$1007, 1))) -> .
A36: [strata 1 e.g. state 1] | B36: Cluster 9 | C36: 45497 | D36: =IF(C36="","-",D35+C36) -> 322608 | E36: =IF(IFERROR(VLOOKUP(B36, K$18:K$1006, 1, FALSE), "no")="no", "no", "yes") -> no | J36: =IF(I36>0, $E$20+J35, ".") -> . | K36: =IF(INDEX(B$28:B$1007, MATCH(J36, D$28:D$1007, 1))=0, ".", INDEX(B$28:B$1007, MATCH(J36, D$28:D$1007, 1))) -> .
A37: [strata 1 e.g. state 1] | B37: Cluster 10 | C37: 2935 | D37: =IF(C37="","-",D36+C37) -> 325543 | E37: =IF(IFERROR(VLOOKUP(B37, K$18:K$1006, 1, FALSE), "no")="no", "no", "yes") -> no | J37: =IF(I37>0, $E$20+J36, ".") -> . | K37: =IF(INDEX(B$28:B$1007, MATCH(J37, D$28:D$1007, 1))=0, ".", INDEX(B$28:B$1007, MATCH(J37, D$28:D$1007, 1))) -> .
A38: [strata 1 e.g. state 1] | B38: Cluster 11 | C38: 88397 | D38: =IF(C38="","-",D37+C38) -> 413940 | E38: =IF(IFERROR(VLOOKUP(B38, K$18:K$1006, 1, FALSE), "no")="no", "no", "yes") -> no | J38: =IF(I38>0, $E$20+J37, ".") -> . | K38: =IF(INDEX(B$28:B$1007, MATCH(J38, D$28:D$1007, 1))=0, ".", INDEX(B$28:B$1007, MATCH(J38, D$28:D$1007, 1))) -> .
A39: [strata 1 e.g. state 1] | B39: Cluster 12 | C39: 74350 | D39: =IF(C39="","-",D38+C39) -> 488290 | E39: =IF(IFERROR(VLOOKUP(B39, K$18:K$1006, 1, FALSE), "no")="no", "no", "yes") -> no | J39: =IF(I39>0, $E$20+J38, ".") -> . | K39: =IF(INDEX(B$28:B$1007, MATCH(J39, D$28:D$1007, 1))=0, ".", INDEX(B$28:B$1007, MATCH(J39, D$28:D$1007, 1))) -> .
A40: [strata 1 e.g. state 1] | B40: Cluster 13 | C40: 38062 | D40: =IF(C40="","-",D39+C40) -> 526352 | E40: =IF(IFERROR(VLOOKUP(B40, K$18:K$1006, 1, FALSE), "no")="no", "no", "yes") -> no | J40: =IF(I40>0, $E$20+J39, ".") -> . | K40: =IF(INDEX(B$28:B$1007, MATCH(J40, D$28:D$1007, 1))=0, ".", INDEX(B$28:B$1007, MATCH(J40, D$28:D$1007, 1))) -> .
... A46: [strata 1 e.g. state 1] | B46: Cluster 19 | C46: 63166 | D46: =IF(C46="","-",D45+C46) -> 767520 | E46: =IF(IFERROR(VLOOKUP(B46, K$18:K$1006, 1, FALSE), "no")="no", "no", "yes") -> no | J46: =IF(I46>0, $E$20+J45, ".") -> . | K46: =IF(INDEX(B$28:B$1007, MATCH(J46, D$28:D$1007, 1))=0, ".", INDEX(B$28:B$1007, MATCH(J46, D$28:D$1007, 1))) -> .
A47: [strata 1 e.g. state 1] | B47: Cluster 20 | C47: 27352 | D47: =IF(C47="","-",D46+C47) -> 794872 | E47: =IF(IFERROR(VLOOKUP(B47, K$18:K$1006, 1, FALSE), "no")="no", "no", "yes") -> no
A48: [strata 1 e.g. state 1] | B48: Cluster 21 | C48: 17812 | D48: =IF(C48="","-",D47+C48) -> 812684 | E48: =IF(IFERROR(VLOOKUP(B48, K$18:K$1006, 1, FALSE), "no")="no", "no", "yes") -> no
A49: [strata 1 e.g. state 1] | B49: Cluster 22 | C49: 62026 | D49: =IF(C49="","-",D48+C49) -> 874710 | E49: =IF(IFERROR(VLOOKUP(B49, K$18:K$1006, 1, FALSE), "no")="no", "no", "yes") -> no
A50: [strata 1 e.g. state 1] | B50: Cluster 1 | C50: 9999 | D50: =IF(C50="","-",D49+C50) -> 884709 | E50: =IF(IFERROR(VLOOKUP(B50, K$18:K$1006, 1, FALSE), "no")="no", "no", "yes") -> yes
A51: [strata 1 e.g. state 1] | B51: Cluster 2 | C51: 26231 | D51: =IF(C51="","-",D50+C51) -> 910940 | E51: =IF(IFERROR(VLOOKUP(B51, K$18:K$1006, 1, FALSE), "no")="no", "no", "yes") -> no
...

Sheet example Urban North
A1: Selected clusters (#) | B1: random id | C1: corresponding cluster
A2: ------ | B2: 0 | C2: ------
A3: 1 | B3: 97638 | C3: Cluster 3
A4: 2 | B4: 195276 | C4: Cluster 5
A5: 3 | B5: 292914 | C5: Cluster 8
A6: 4 | B6: 390552 | C6: Cluster 10
A7: 5 | B7: 488190 | C7: Cluster 11
A8: 6 | B8: 585828 | C8: Cluster 15
A9: 7 | B9: 683466 | C9: Cluster 16
